<?xml version="1.0" ?>
<robot xmlns:xacro="http://ros.org/wiki/xacro">
<xacro:macro name="motoman_gp7" params="prefix">
    <xacro:include filename="$(find motoman_resources)/urdf/common_materials.xacro"/>

    <!-- link list -->
    <link name="${prefix}base_link">
        <visual>
            <geometry>
                <mesh filename="package://motoman_gp7_support/meshes/visual/gp7_base_link.stl"/>
            </geometry>
            <xacro:material_yaskawa_blue/>
        </visual>
        <collision>
            <geometry>
                <mesh filename="package://motoman_gp7_support/meshes/collision/gp7_base_link.stl"/>
            </geometry>
        </collision>
    </link>
    <link name="${prefix}link_1">
        <visual>
            <geometry>
                <mesh filename="package://motoman_gp7_support/meshes/visual/gp7_link_1_s.stl"/>
            </geometry>
            <xacro:material_yaskawa_blue/>
        </visual>
        <collision>
            <geometry>
                <mesh filename="package://motoman_gp7_support/meshes/collision/gp7_link_1_s.stl"/>
            </geometry>
        </collision>
    </link>
    <link name="${prefix}link_2">
        <visual>
            <geometry>
                <mesh filename="package://motoman_gp7_support/meshes/visual/gp7_link_2_l.stl"/>
            </geometry>
            <xacro:material_yaskawa_blue/>
        </visual>
        <collision>
            <geometry>
                <mesh filename="package://motoman_gp7_support/meshes/collision/gp7_link_2_l.stl"/>
            </geometry>
        </collision>
    </link>
    <link name="${prefix}link_3">
        <visual>
            <geometry>
                <mesh filename="package://motoman_gp7_support/meshes/visual/gp7_link_3_u.stl"/>
            </geometry>
            <xacro:material_yaskawa_blue/>
        </visual>
        <collision>
            <geometry>
                <mesh filename="package://motoman_gp7_support/meshes/collision/gp7_link_3_u.stl"/>
            </geometry>
        </collision>
    </link>
    <link name="${prefix}link_4">
        <visual>
            <geometry>
                <mesh filename="package://motoman_gp7_support/meshes/visual/gp7_link_4_r.stl"/>
            </geometry>
            <xacro:material_yaskawa_blue/>
        </visual>
        <collision>
            <geometry>
                <mesh filename="package://motoman_gp7_support/meshes/collision/gp7_link_4_r.stl"/>
            </geometry>
        </collision>
    </link>
    <link name="${prefix}link_5">
        <visual>
            <geometry>
                <mesh filename="package://motoman_gp7_support/meshes/visual/gp7_link_5_b.stl"/>
            </geometry>
            <xacro:material_yaskawa_blue/>
        </visual>
        <collision>
            <geometry>
                <mesh filename="package://motoman_gp7_support/meshes/collision/gp7_link_5_b.stl"/>
            </geometry>
        </collision>
    </link>
    <link name="${prefix}link_6">
        <visual>
            <geometry>
                <mesh filename="package://motoman_gp7_support/meshes/visual/gp7_link_6_t.stl"/>
            </geometry>
            <xacro:material_yaskawa_blue/>
        </visual>
        <collision>
            <geometry>
                <mesh filename="package://motoman_gp7_support/meshes/collision/gp7_link_6_t.stl"/>
            </geometry>
        </collision>
    </link>
    <link name="${prefix}tool0"/>
    <link name="${prefix}flange"/>
    <!-- end of link list -->

    <!-- joint list -->
    <joint name="${prefix}joint_1" type="revolute">
        <parent link="${prefix}base_link"/>
        <child link="${prefix}link_1"/>
        <origin xyz="0 0 0.330" rpy="0 0 0" />
        <axis xyz="0 0 1" />
        <limit lower="-2.9670" upper="2.9670" effort="212.66" velocity="6.5448"/>
    </joint>
    <joint name="${prefix}joint_2" type="revolute">
        <parent link="${prefix}link_1"/>
        <child link="${prefix}link_2"/>
        <origin xyz="0.040 0 0" rpy="0 0 0" />
        <axis xyz="0 1 0" />
        <limit lower="-1.1344" upper="2.5307" effort="205.80" velocity="5.4977"/>
    </joint>
    <joint name="${prefix}joint_3" type="revolute">
        <parent link="${prefix}link_2"/>
        <child link="${prefix}link_3"/>
        <origin xyz="0 0 0.445" rpy="0 0 0" />
        <axis xyz="0 -1 0" />
        <limit lower="-1.2217" upper="3.3161" effort="106.82" velocity="7.1558"/>
    </joint>
    <joint name="${prefix}joint_4" type="revolute">
        <parent link="${prefix}link_3"/>
        <child link="${prefix}link_4"/>
        <origin xyz="0.440 0 0.040" rpy="0 0 0" />
        <axis xyz="-1 0 0" />
        <limit lower="-3.3161" upper="3.3161" effort="55.86" velocity="9.5993"/>
    </joint>
    <joint name="${prefix}joint_5" type="revolute">
        <parent link="${prefix}link_4"/>
        <child link="${prefix}link_5"/>
        <origin xyz="0 0 0" rpy="0 0 0" />
        <axis xyz="0 -1 0" />
        <limit lower="-2.3561" upper="2.3561" effort="32.68" velocity="9.5993"/>
    </joint>
    <joint name="${prefix}joint_6" type="revolute">
        <parent link="${prefix}link_5"/>
        <child link="${prefix}link_6"/>
        <origin xyz="0 0 0" rpy="0 0 0" />
        <axis xyz="-1 0 0" />
        <limit lower="-6.2944" upper="6.2944" effort="22.54" velocity="17.4845"/>
    </joint>
    <joint name="${prefix}joint_6_t-tool0" type="fixed">
        <origin xyz="0.080 0 0" rpy="3.1415926 -1.570796 0"/>
        <parent link="${prefix}link_6"/>
        <child link="${prefix}tool0"/>
    </joint>
    <joint name="${prefix}joint_6_t-flange" type="fixed">
        <origin xyz="0.080 0 0" rpy="0 0 0"/>
        <parent link="${prefix}link_6"/>
        <child link="${prefix}flange"/>
    </joint>
    <!-- end of joint list -->

    <!-- ROS base_link to Robot Manufacturer World Coordinates transform -->
    <link name="${prefix}base" />
    <joint name="${prefix}base_link-base" type="fixed">
        <origin xyz="0 0 0.330" rpy="0 0 0"/>
        <parent link="${prefix}base_link"/>
        <child link="${prefix}base"/>   
    </joint>

    <material name="grey">
        <color rgba="0.9 0.9 0.9 1"/>
    </material>

     <material name="dark grey">
        <color rgba="0.4 0.4 0.4 1"/>
    </material>

    <link name="cart">
        <visual>
        <geometry>
            <box size="1.21 0.621 0.74"/>
        </geometry>
        <material name="grey"/>
        <origin rpy="0 0 0" xyz="0 0 0.37"/>
        </visual>
    </link>
    <joint name="cart_to_base" type="fixed">
        <parent link="cart"/>
        <child link="base_link"/>
        <origin xyz="-0.4035 0 0.74"/>
    </joint>

    <link name="press">
        <visual>
            <geometry>
                <mesh filename="package://aims_gp7wc_support/meshes/press_model.STL"/>
            </geometry>
            <material name="dark grey"/>
            <origin rpy="${radians(90)} 0 -${radians(90)}" xyz="0 0 0"/>
        </visual>
    </link>

     <joint name="press_to_cart" type="fixed">
        <parent link="cart"/>
        <child link="press"/>
        <origin xyz="0.143 0.1505 0.74"/>
    </joint>


    </xacro:macro>

</robot>

